{"uid":"34eb0bdf1dac987a","name":"User logs in","fullName":"Login functionality: User logs in","historyId":"b7205aedd34fc280935fc50ad1179fb2","time":{"start":1752060534868,"stop":1752060536958,"duration":2090},"status":"broken","statusMessage":"selenium.common.exceptions.SessionNotCreatedException: Message: session not created: probably user data directory is already in use, please specify a unique value for --user-data-dir argument, or don't use --user-data-dir; For documentation on this error, please visit: https://www.selenium.dev/documentation/webdriver/troubleshooting/errors#sessionnotcreatedexception\nStacktrace:\n#0 0x5640d641226a <unknown>\n#1 0x5640d5ebcab0 <unknown>\n#2 0x5640d5ef78ac <unknown>\n#3 0x5640d5ef2307 <unknown>\n#4 0x5640d5f42696 <unknown>\n#5 0x5640d5f41d56 <unknown>\n#6 0x5640d5f33f73 <unknown>\n#7 0x5640d5f00aeb <unknown>\n#8 0x5640d5f01751 <unknown>\n#9 0x5640d63d6b7b <unknown>\n#10 0x5640d63da959 <unknown>\n#11 0x5640d63bd959 <unknown>\n#12 0x5640d63db518 <unknown>\n#13 0x5640d63a210f <unknown>\n#14 0x5640d63ff918 <unknown>\n#15 0x5640d63ffaf6 <unknown>\n#16 0x5640d6411586 <unknown>\n#17 0x7fe05789caa4 <unknown>\n#18 0x7fe057929c3c <unknown>\n\n","statusTrace":"  File \"/opt/hostedtoolcache/Python/3.10.18/x64/lib/python3.10/site-packages/behave/model.py\", line 1329, in run\n    match.run(runner.context)\n  File \"/opt/hostedtoolcache/Python/3.10.18/x64/lib/python3.10/site-packages/behave/matchers.py\", line 98, in run\n    self.func(context, *args, **kwargs)\n  File \"features/steps/login_steps.py\", line 12, in step_user_on_login_page\n    context.driver = webdriver.Chrome()\n  File \"/opt/hostedtoolcache/Python/3.10.18/x64/lib/python3.10/site-packages/selenium/webdriver/chrome/webdriver.py\", line 47, in __init__\n    super().__init__(\n  File \"/opt/hostedtoolcache/Python/3.10.18/x64/lib/python3.10/site-packages/selenium/webdriver/chromium/webdriver.py\", line 69, in __init__\n    super().__init__(command_executor=executor, options=options)\n  File \"/opt/hostedtoolcache/Python/3.10.18/x64/lib/python3.10/site-packages/selenium/webdriver/remote/webdriver.py\", line 261, in __init__\n    self.start_session(capabilities)\n  File \"/opt/hostedtoolcache/Python/3.10.18/x64/lib/python3.10/site-packages/selenium/webdriver/remote/webdriver.py\", line 362, in start_session\n    response = self.execute(Command.NEW_SESSION, caps)[\"value\"]\n  File \"/opt/hostedtoolcache/Python/3.10.18/x64/lib/python3.10/site-packages/selenium/webdriver/remote/webdriver.py\", line 454, in execute\n    self.error_handler.check_response(response)\n  File \"/opt/hostedtoolcache/Python/3.10.18/x64/lib/python3.10/site-packages/selenium/webdriver/remote/errorhandler.py\", line 232, in check_response\n    raise exception_class(message, screen, stacktrace)\n","flaky":false,"newFailed":false,"newBroken":false,"newPassed":false,"retriesCount":1,"retriesStatusChange":true,"beforeStages":[],"testStage":{"status":"broken","statusMessage":"selenium.common.exceptions.SessionNotCreatedException: Message: session not created: probably user data directory is already in use, please specify a unique value for --user-data-dir argument, or don't use --user-data-dir; For documentation on this error, please visit: https://www.selenium.dev/documentation/webdriver/troubleshooting/errors#sessionnotcreatedexception\nStacktrace:\n#0 0x5640d641226a <unknown>\n#1 0x5640d5ebcab0 <unknown>\n#2 0x5640d5ef78ac <unknown>\n#3 0x5640d5ef2307 <unknown>\n#4 0x5640d5f42696 <unknown>\n#5 0x5640d5f41d56 <unknown>\n#6 0x5640d5f33f73 <unknown>\n#7 0x5640d5f00aeb <unknown>\n#8 0x5640d5f01751 <unknown>\n#9 0x5640d63d6b7b <unknown>\n#10 0x5640d63da959 <unknown>\n#11 0x5640d63bd959 <unknown>\n#12 0x5640d63db518 <unknown>\n#13 0x5640d63a210f <unknown>\n#14 0x5640d63ff918 <unknown>\n#15 0x5640d63ffaf6 <unknown>\n#16 0x5640d6411586 <unknown>\n#17 0x7fe05789caa4 <unknown>\n#18 0x7fe057929c3c <unknown>\n\n","statusTrace":"  File \"/opt/hostedtoolcache/Python/3.10.18/x64/lib/python3.10/site-packages/behave/model.py\", line 1329, in run\n    match.run(runner.context)\n  File \"/opt/hostedtoolcache/Python/3.10.18/x64/lib/python3.10/site-packages/behave/matchers.py\", line 98, in run\n    self.func(context, *args, **kwargs)\n  File \"features/steps/login_steps.py\", line 12, in step_user_on_login_page\n    context.driver = webdriver.Chrome()\n  File \"/opt/hostedtoolcache/Python/3.10.18/x64/lib/python3.10/site-packages/selenium/webdriver/chrome/webdriver.py\", line 47, in __init__\n    super().__init__(\n  File \"/opt/hostedtoolcache/Python/3.10.18/x64/lib/python3.10/site-packages/selenium/webdriver/chromium/webdriver.py\", line 69, in __init__\n    super().__init__(command_executor=executor, options=options)\n  File \"/opt/hostedtoolcache/Python/3.10.18/x64/lib/python3.10/site-packages/selenium/webdriver/remote/webdriver.py\", line 261, in __init__\n    self.start_session(capabilities)\n  File \"/opt/hostedtoolcache/Python/3.10.18/x64/lib/python3.10/site-packages/selenium/webdriver/remote/webdriver.py\", line 362, in start_session\n    response = self.execute(Command.NEW_SESSION, caps)[\"value\"]\n  File \"/opt/hostedtoolcache/Python/3.10.18/x64/lib/python3.10/site-packages/selenium/webdriver/remote/webdriver.py\", line 454, in execute\n    self.error_handler.check_response(response)\n  File \"/opt/hostedtoolcache/Python/3.10.18/x64/lib/python3.10/site-packages/selenium/webdriver/remote/errorhandler.py\", line 232, in check_response\n    raise exception_class(message, screen, stacktrace)\n","steps":[{"name":"Given the user is on the saucedemo login page","time":{"start":1752060534869,"stop":1752060536958,"duration":2089},"status":"broken","statusMessage":"selenium.common.exceptions.SessionNotCreatedException: Message: session not created: probably user data directory is already in use, please specify a unique value for --user-data-dir argument, or don't use --user-data-dir; For documentation on this error, please visit: https://www.selenium.dev/documentation/webdriver/troubleshooting/errors#sessionnotcreatedexception\nStacktrace:\n#0 0x5640d641226a <unknown>\n#1 0x5640d5ebcab0 <unknown>\n#2 0x5640d5ef78ac <unknown>\n#3 0x5640d5ef2307 <unknown>\n#4 0x5640d5f42696 <unknown>\n#5 0x5640d5f41d56 <unknown>\n#6 0x5640d5f33f73 <unknown>\n#7 0x5640d5f00aeb <unknown>\n#8 0x5640d5f01751 <unknown>\n#9 0x5640d63d6b7b <unknown>\n#10 0x5640d63da959 <unknown>\n#11 0x5640d63bd959 <unknown>\n#12 0x5640d63db518 <unknown>\n#13 0x5640d63a210f <unknown>\n#14 0x5640d63ff918 <unknown>\n#15 0x5640d63ffaf6 <unknown>\n#16 0x5640d6411586 <unknown>\n#17 0x7fe05789caa4 <unknown>\n#18 0x7fe057929c3c <unknown>\n\n","statusTrace":"  File \"/opt/hostedtoolcache/Python/3.10.18/x64/lib/python3.10/site-packages/behave/model.py\", line 1329, in run\n    match.run(runner.context)\n  File \"/opt/hostedtoolcache/Python/3.10.18/x64/lib/python3.10/site-packages/behave/matchers.py\", line 98, in run\n    self.func(context, *args, **kwargs)\n  File \"features/steps/login_steps.py\", line 12, in step_user_on_login_page\n    context.driver = webdriver.Chrome()\n  File \"/opt/hostedtoolcache/Python/3.10.18/x64/lib/python3.10/site-packages/selenium/webdriver/chrome/webdriver.py\", line 47, in __init__\n    super().__init__(\n  File \"/opt/hostedtoolcache/Python/3.10.18/x64/lib/python3.10/site-packages/selenium/webdriver/chromium/webdriver.py\", line 69, in __init__\n    super().__init__(command_executor=executor, options=options)\n  File \"/opt/hostedtoolcache/Python/3.10.18/x64/lib/python3.10/site-packages/selenium/webdriver/remote/webdriver.py\", line 261, in __init__\n    self.start_session(capabilities)\n  File \"/opt/hostedtoolcache/Python/3.10.18/x64/lib/python3.10/site-packages/selenium/webdriver/remote/webdriver.py\", line 362, in start_session\n    response = self.execute(Command.NEW_SESSION, caps)[\"value\"]\n  File \"/opt/hostedtoolcache/Python/3.10.18/x64/lib/python3.10/site-packages/selenium/webdriver/remote/webdriver.py\", line 454, in execute\n    self.error_handler.check_response(response)\n  File \"/opt/hostedtoolcache/Python/3.10.18/x64/lib/python3.10/site-packages/selenium/webdriver/remote/errorhandler.py\", line 232, in check_response\n    raise exception_class(message, screen, stacktrace)\n","steps":[],"attachments":[],"parameters":[],"shouldDisplayMessage":true,"stepsCount":0,"attachmentsCount":0,"hasContent":true,"attachmentStep":false},{"name":"When the user logs in","time":{"start":1752060536958,"stop":1752060536958,"duration":0},"status":"skipped","steps":[],"attachments":[],"parameters":[],"shouldDisplayMessage":false,"stepsCount":0,"attachmentsCount":0,"hasContent":false,"attachmentStep":false},{"name":"Then the user should see the products page","time":{"start":1752060536958,"stop":1752060536958,"duration":0},"status":"skipped","steps":[],"attachments":[],"parameters":[],"shouldDisplayMessage":false,"stepsCount":0,"attachmentsCount":0,"hasContent":false,"attachmentStep":false}],"attachments":[],"parameters":[],"shouldDisplayMessage":false,"stepsCount":3,"attachmentsCount":0,"hasContent":true,"attachmentStep":false},"afterStages":[],"labels":[{"name":"severity","value":"normal"},{"name":"tag","value":"smoke"},{"name":"feature","value":"Login functionality"},{"name":"framework","value":"behave"},{"name":"language","value":"cpython3"},{"name":"resultFormat","value":"allure2"}],"parameters":[],"links":[],"hidden":false,"retry":false,"extra":{"severity":"normal","retries":[{"uid":"d7ee8bae671b16a4","status":"passed","time":{"start":1752004648860,"stop":1752004674584,"duration":25724}}],"categories":[{"name":"Test defects","matchedStatuses":[],"flaky":false}],"tags":["smoke"]},"source":"34eb0bdf1dac987a.json","parameterValues":[]}