{"uid":"394e4ca761d31865","name":"User logs in with wrong password","fullName":"Login functionality: User logs in with wrong password","historyId":"3bc84a241599c28d05e3064c8f7e74a5","time":{"start":1752069212220,"stop":1752069221104,"duration":8884},"status":"broken","statusMessage":"selenium.common.exceptions.SessionNotCreatedException: Message: session not created: probably user data directory is already in use, please specify a unique value for --user-data-dir argument, or don't use --user-data-dir; For documentation on this error, please visit: https://www.selenium.dev/documentation/webdriver/troubleshooting/errors#sessionnotcreatedexception\nStacktrace:\n#0 0x55cec712a26a <unknown>\n#1 0x55cec6bd4ab0 <unknown>\n#2 0x55cec6c0f8ac <unknown>\n#3 0x55cec6c0a307 <unknown>\n#4 0x55cec6c5a696 <unknown>\n#5 0x55cec6c59d56 <unknown>\n#6 0x55cec6c4bf73 <unknown>\n#7 0x55cec6c18aeb <unknown>\n#8 0x55cec6c19751 <unknown>\n#9 0x55cec70eeb7b <unknown>\n#10 0x55cec70f2959 <unknown>\n#11 0x55cec70d5959 <unknown>\n#12 0x55cec70f3518 <unknown>\n#13 0x55cec70ba10f <unknown>\n#14 0x55cec7117918 <unknown>\n#15 0x55cec7117af6 <unknown>\n#16 0x55cec7129586 <unknown>\n#17 0x7f711889caa4 <unknown>\n#18 0x7f7118929c3c <unknown>\n\n","statusTrace":"  File \"/opt/hostedtoolcache/Python/3.10.18/x64/lib/python3.10/site-packages/behave/model.py\", line 1329, in run\n    match.run(runner.context)\n  File \"/opt/hostedtoolcache/Python/3.10.18/x64/lib/python3.10/site-packages/behave/matchers.py\", line 98, in run\n    self.func(context, *args, **kwargs)\n  File \"features/steps/login_steps.py\", line 12, in step_user_on_login_page\n    context.driver = webdriver.Chrome()\n  File \"/opt/hostedtoolcache/Python/3.10.18/x64/lib/python3.10/site-packages/selenium/webdriver/chrome/webdriver.py\", line 47, in __init__\n    super().__init__(\n  File \"/opt/hostedtoolcache/Python/3.10.18/x64/lib/python3.10/site-packages/selenium/webdriver/chromium/webdriver.py\", line 69, in __init__\n    super().__init__(command_executor=executor, options=options)\n  File \"/opt/hostedtoolcache/Python/3.10.18/x64/lib/python3.10/site-packages/selenium/webdriver/remote/webdriver.py\", line 261, in __init__\n    self.start_session(capabilities)\n  File \"/opt/hostedtoolcache/Python/3.10.18/x64/lib/python3.10/site-packages/selenium/webdriver/remote/webdriver.py\", line 362, in start_session\n    response = self.execute(Command.NEW_SESSION, caps)[\"value\"]\n  File \"/opt/hostedtoolcache/Python/3.10.18/x64/lib/python3.10/site-packages/selenium/webdriver/remote/webdriver.py\", line 454, in execute\n    self.error_handler.check_response(response)\n  File \"/opt/hostedtoolcache/Python/3.10.18/x64/lib/python3.10/site-packages/selenium/webdriver/remote/errorhandler.py\", line 232, in check_response\n    raise exception_class(message, screen, stacktrace)\n","flaky":false,"newFailed":false,"newBroken":false,"newPassed":false,"retriesCount":1,"retriesStatusChange":true,"beforeStages":[],"testStage":{"status":"broken","statusMessage":"selenium.common.exceptions.SessionNotCreatedException: Message: session not created: probably user data directory is already in use, please specify a unique value for --user-data-dir argument, or don't use --user-data-dir; For documentation on this error, please visit: https://www.selenium.dev/documentation/webdriver/troubleshooting/errors#sessionnotcreatedexception\nStacktrace:\n#0 0x55cec712a26a <unknown>\n#1 0x55cec6bd4ab0 <unknown>\n#2 0x55cec6c0f8ac <unknown>\n#3 0x55cec6c0a307 <unknown>\n#4 0x55cec6c5a696 <unknown>\n#5 0x55cec6c59d56 <unknown>\n#6 0x55cec6c4bf73 <unknown>\n#7 0x55cec6c18aeb <unknown>\n#8 0x55cec6c19751 <unknown>\n#9 0x55cec70eeb7b <unknown>\n#10 0x55cec70f2959 <unknown>\n#11 0x55cec70d5959 <unknown>\n#12 0x55cec70f3518 <unknown>\n#13 0x55cec70ba10f <unknown>\n#14 0x55cec7117918 <unknown>\n#15 0x55cec7117af6 <unknown>\n#16 0x55cec7129586 <unknown>\n#17 0x7f711889caa4 <unknown>\n#18 0x7f7118929c3c <unknown>\n\n","statusTrace":"  File \"/opt/hostedtoolcache/Python/3.10.18/x64/lib/python3.10/site-packages/behave/model.py\", line 1329, in run\n    match.run(runner.context)\n  File \"/opt/hostedtoolcache/Python/3.10.18/x64/lib/python3.10/site-packages/behave/matchers.py\", line 98, in run\n    self.func(context, *args, **kwargs)\n  File \"features/steps/login_steps.py\", line 12, in step_user_on_login_page\n    context.driver = webdriver.Chrome()\n  File \"/opt/hostedtoolcache/Python/3.10.18/x64/lib/python3.10/site-packages/selenium/webdriver/chrome/webdriver.py\", line 47, in __init__\n    super().__init__(\n  File \"/opt/hostedtoolcache/Python/3.10.18/x64/lib/python3.10/site-packages/selenium/webdriver/chromium/webdriver.py\", line 69, in __init__\n    super().__init__(command_executor=executor, options=options)\n  File \"/opt/hostedtoolcache/Python/3.10.18/x64/lib/python3.10/site-packages/selenium/webdriver/remote/webdriver.py\", line 261, in __init__\n    self.start_session(capabilities)\n  File \"/opt/hostedtoolcache/Python/3.10.18/x64/lib/python3.10/site-packages/selenium/webdriver/remote/webdriver.py\", line 362, in start_session\n    response = self.execute(Command.NEW_SESSION, caps)[\"value\"]\n  File \"/opt/hostedtoolcache/Python/3.10.18/x64/lib/python3.10/site-packages/selenium/webdriver/remote/webdriver.py\", line 454, in execute\n    self.error_handler.check_response(response)\n  File \"/opt/hostedtoolcache/Python/3.10.18/x64/lib/python3.10/site-packages/selenium/webdriver/remote/errorhandler.py\", line 232, in check_response\n    raise exception_class(message, screen, stacktrace)\n","steps":[{"name":"Given the user is on the saucedemo login page","time":{"start":1752069212221,"stop":1752069221103,"duration":8882},"status":"broken","statusMessage":"selenium.common.exceptions.SessionNotCreatedException: Message: session not created: probably user data directory is already in use, please specify a unique value for --user-data-dir argument, or don't use --user-data-dir; For documentation on this error, please visit: https://www.selenium.dev/documentation/webdriver/troubleshooting/errors#sessionnotcreatedexception\nStacktrace:\n#0 0x55cec712a26a <unknown>\n#1 0x55cec6bd4ab0 <unknown>\n#2 0x55cec6c0f8ac <unknown>\n#3 0x55cec6c0a307 <unknown>\n#4 0x55cec6c5a696 <unknown>\n#5 0x55cec6c59d56 <unknown>\n#6 0x55cec6c4bf73 <unknown>\n#7 0x55cec6c18aeb <unknown>\n#8 0x55cec6c19751 <unknown>\n#9 0x55cec70eeb7b <unknown>\n#10 0x55cec70f2959 <unknown>\n#11 0x55cec70d5959 <unknown>\n#12 0x55cec70f3518 <unknown>\n#13 0x55cec70ba10f <unknown>\n#14 0x55cec7117918 <unknown>\n#15 0x55cec7117af6 <unknown>\n#16 0x55cec7129586 <unknown>\n#17 0x7f711889caa4 <unknown>\n#18 0x7f7118929c3c <unknown>\n\n","statusTrace":"  File \"/opt/hostedtoolcache/Python/3.10.18/x64/lib/python3.10/site-packages/behave/model.py\", line 1329, in run\n    match.run(runner.context)\n  File \"/opt/hostedtoolcache/Python/3.10.18/x64/lib/python3.10/site-packages/behave/matchers.py\", line 98, in run\n    self.func(context, *args, **kwargs)\n  File \"features/steps/login_steps.py\", line 12, in step_user_on_login_page\n    context.driver = webdriver.Chrome()\n  File \"/opt/hostedtoolcache/Python/3.10.18/x64/lib/python3.10/site-packages/selenium/webdriver/chrome/webdriver.py\", line 47, in __init__\n    super().__init__(\n  File \"/opt/hostedtoolcache/Python/3.10.18/x64/lib/python3.10/site-packages/selenium/webdriver/chromium/webdriver.py\", line 69, in __init__\n    super().__init__(command_executor=executor, options=options)\n  File \"/opt/hostedtoolcache/Python/3.10.18/x64/lib/python3.10/site-packages/selenium/webdriver/remote/webdriver.py\", line 261, in __init__\n    self.start_session(capabilities)\n  File \"/opt/hostedtoolcache/Python/3.10.18/x64/lib/python3.10/site-packages/selenium/webdriver/remote/webdriver.py\", line 362, in start_session\n    response = self.execute(Command.NEW_SESSION, caps)[\"value\"]\n  File \"/opt/hostedtoolcache/Python/3.10.18/x64/lib/python3.10/site-packages/selenium/webdriver/remote/webdriver.py\", line 454, in execute\n    self.error_handler.check_response(response)\n  File \"/opt/hostedtoolcache/Python/3.10.18/x64/lib/python3.10/site-packages/selenium/webdriver/remote/errorhandler.py\", line 232, in check_response\n    raise exception_class(message, screen, stacktrace)\n","steps":[],"attachments":[],"parameters":[],"shouldDisplayMessage":true,"stepsCount":0,"attachmentsCount":0,"hasContent":true,"attachmentStep":false},{"name":"When the user logs in with username \"standard_user\" and password \"wrong_pass\"","time":{"start":1752069221104,"stop":1752069221104,"duration":0},"status":"skipped","steps":[],"attachments":[],"parameters":[],"shouldDisplayMessage":false,"stepsCount":0,"attachmentsCount":0,"hasContent":false,"attachmentStep":false},{"name":"Then the user should see an error message","time":{"start":1752069221104,"stop":1752069221104,"duration":0},"status":"skipped","steps":[],"attachments":[],"parameters":[],"shouldDisplayMessage":false,"stepsCount":0,"attachmentsCount":0,"hasContent":false,"attachmentStep":false}],"attachments":[],"parameters":[],"shouldDisplayMessage":false,"stepsCount":3,"attachmentsCount":0,"hasContent":true,"attachmentStep":false},"afterStages":[],"labels":[{"name":"severity","value":"normal"},{"name":"tag","value":"smoke"},{"name":"feature","value":"Login functionality"},{"name":"framework","value":"behave"},{"name":"language","value":"cpython3"},{"name":"resultFormat","value":"allure2"}],"parameters":[],"links":[],"hidden":false,"retry":false,"extra":{"severity":"normal","retries":[{"uid":"585ef3baa6d23293","status":"passed","time":{"start":1752061561782,"stop":1752061585874,"duration":24092}}],"categories":[{"name":"Test defects","matchedStatuses":[],"flaky":false}],"tags":["smoke"]},"source":"394e4ca761d31865.json","parameterValues":[]}