{"uid":"decfbc4cdf88c971","name":"User logs in with invalid credentials -- @1.1 ","fullName":"Login functionality on saucedemo: User logs in with invalid credentials","historyId":"25c963a5bc4aa44cad56fb7f9490a71f","time":{"start":1752092565266,"stop":1752092569608,"duration":4342},"status":"broken","statusMessage":"selenium.common.exceptions.SessionNotCreatedException: Message: session not created: probably user data directory is already in use, please specify a unique value for --user-data-dir argument, or don't use --user-data-dir; For documentation on this error, please visit: https://www.selenium.dev/documentation/webdriver/troubleshooting/errors#sessionnotcreatedexception\nStacktrace:\n#0 0x56415c70126a <unknown>\n#1 0x56415c1abab0 <unknown>\n#2 0x56415c1e68ac <unknown>\n#3 0x56415c1e1307 <unknown>\n#4 0x56415c231696 <unknown>\n#5 0x56415c230d56 <unknown>\n#6 0x56415c222f73 <unknown>\n#7 0x56415c1efaeb <unknown>\n#8 0x56415c1f0751 <unknown>\n#9 0x56415c6c5b7b <unknown>\n#10 0x56415c6c9959 <unknown>\n#11 0x56415c6ac959 <unknown>\n#12 0x56415c6ca518 <unknown>\n#13 0x56415c69110f <unknown>\n#14 0x56415c6ee918 <unknown>\n#15 0x56415c6eeaf6 <unknown>\n#16 0x56415c700586 <unknown>\n#17 0x7f8a8609caa4 <unknown>\n#18 0x7f8a86129c3c <unknown>\n\n","statusTrace":"  File \"/opt/hostedtoolcache/Python/3.10.18/x64/lib/python3.10/site-packages/behave/model.py\", line 1329, in run\n    match.run(runner.context)\n  File \"/opt/hostedtoolcache/Python/3.10.18/x64/lib/python3.10/site-packages/behave/matchers.py\", line 98, in run\n    self.func(context, *args, **kwargs)\n  File \"features/steps/login_steps.py\", line 12, in step_user_on_login_page\n    context.driver = webdriver.Chrome()\n  File \"/opt/hostedtoolcache/Python/3.10.18/x64/lib/python3.10/site-packages/selenium/webdriver/chrome/webdriver.py\", line 47, in __init__\n    super().__init__(\n  File \"/opt/hostedtoolcache/Python/3.10.18/x64/lib/python3.10/site-packages/selenium/webdriver/chromium/webdriver.py\", line 69, in __init__\n    super().__init__(command_executor=executor, options=options)\n  File \"/opt/hostedtoolcache/Python/3.10.18/x64/lib/python3.10/site-packages/selenium/webdriver/remote/webdriver.py\", line 261, in __init__\n    self.start_session(capabilities)\n  File \"/opt/hostedtoolcache/Python/3.10.18/x64/lib/python3.10/site-packages/selenium/webdriver/remote/webdriver.py\", line 362, in start_session\n    response = self.execute(Command.NEW_SESSION, caps)[\"value\"]\n  File \"/opt/hostedtoolcache/Python/3.10.18/x64/lib/python3.10/site-packages/selenium/webdriver/remote/webdriver.py\", line 454, in execute\n    self.error_handler.check_response(response)\n  File \"/opt/hostedtoolcache/Python/3.10.18/x64/lib/python3.10/site-packages/selenium/webdriver/remote/errorhandler.py\", line 232, in check_response\n    raise exception_class(message, screen, stacktrace)\n","flaky":false,"newFailed":false,"newBroken":false,"newPassed":false,"retriesCount":0,"retriesStatusChange":false,"beforeStages":[],"testStage":{"status":"broken","statusMessage":"selenium.common.exceptions.SessionNotCreatedException: Message: session not created: probably user data directory is already in use, please specify a unique value for --user-data-dir argument, or don't use --user-data-dir; For documentation on this error, please visit: https://www.selenium.dev/documentation/webdriver/troubleshooting/errors#sessionnotcreatedexception\nStacktrace:\n#0 0x56415c70126a <unknown>\n#1 0x56415c1abab0 <unknown>\n#2 0x56415c1e68ac <unknown>\n#3 0x56415c1e1307 <unknown>\n#4 0x56415c231696 <unknown>\n#5 0x56415c230d56 <unknown>\n#6 0x56415c222f73 <unknown>\n#7 0x56415c1efaeb <unknown>\n#8 0x56415c1f0751 <unknown>\n#9 0x56415c6c5b7b <unknown>\n#10 0x56415c6c9959 <unknown>\n#11 0x56415c6ac959 <unknown>\n#12 0x56415c6ca518 <unknown>\n#13 0x56415c69110f <unknown>\n#14 0x56415c6ee918 <unknown>\n#15 0x56415c6eeaf6 <unknown>\n#16 0x56415c700586 <unknown>\n#17 0x7f8a8609caa4 <unknown>\n#18 0x7f8a86129c3c <unknown>\n\n","statusTrace":"  File \"/opt/hostedtoolcache/Python/3.10.18/x64/lib/python3.10/site-packages/behave/model.py\", line 1329, in run\n    match.run(runner.context)\n  File \"/opt/hostedtoolcache/Python/3.10.18/x64/lib/python3.10/site-packages/behave/matchers.py\", line 98, in run\n    self.func(context, *args, **kwargs)\n  File \"features/steps/login_steps.py\", line 12, in step_user_on_login_page\n    context.driver = webdriver.Chrome()\n  File \"/opt/hostedtoolcache/Python/3.10.18/x64/lib/python3.10/site-packages/selenium/webdriver/chrome/webdriver.py\", line 47, in __init__\n    super().__init__(\n  File \"/opt/hostedtoolcache/Python/3.10.18/x64/lib/python3.10/site-packages/selenium/webdriver/chromium/webdriver.py\", line 69, in __init__\n    super().__init__(command_executor=executor, options=options)\n  File \"/opt/hostedtoolcache/Python/3.10.18/x64/lib/python3.10/site-packages/selenium/webdriver/remote/webdriver.py\", line 261, in __init__\n    self.start_session(capabilities)\n  File \"/opt/hostedtoolcache/Python/3.10.18/x64/lib/python3.10/site-packages/selenium/webdriver/remote/webdriver.py\", line 362, in start_session\n    response = self.execute(Command.NEW_SESSION, caps)[\"value\"]\n  File \"/opt/hostedtoolcache/Python/3.10.18/x64/lib/python3.10/site-packages/selenium/webdriver/remote/webdriver.py\", line 454, in execute\n    self.error_handler.check_response(response)\n  File \"/opt/hostedtoolcache/Python/3.10.18/x64/lib/python3.10/site-packages/selenium/webdriver/remote/errorhandler.py\", line 232, in check_response\n    raise exception_class(message, screen, stacktrace)\n","steps":[{"name":"Given the user is on the saucedemo login page","time":{"start":1752092565267,"stop":1752092569608,"duration":4341},"status":"broken","statusMessage":"selenium.common.exceptions.SessionNotCreatedException: Message: session not created: probably user data directory is already in use, please specify a unique value for --user-data-dir argument, or don't use --user-data-dir; For documentation on this error, please visit: https://www.selenium.dev/documentation/webdriver/troubleshooting/errors#sessionnotcreatedexception\nStacktrace:\n#0 0x56415c70126a <unknown>\n#1 0x56415c1abab0 <unknown>\n#2 0x56415c1e68ac <unknown>\n#3 0x56415c1e1307 <unknown>\n#4 0x56415c231696 <unknown>\n#5 0x56415c230d56 <unknown>\n#6 0x56415c222f73 <unknown>\n#7 0x56415c1efaeb <unknown>\n#8 0x56415c1f0751 <unknown>\n#9 0x56415c6c5b7b <unknown>\n#10 0x56415c6c9959 <unknown>\n#11 0x56415c6ac959 <unknown>\n#12 0x56415c6ca518 <unknown>\n#13 0x56415c69110f <unknown>\n#14 0x56415c6ee918 <unknown>\n#15 0x56415c6eeaf6 <unknown>\n#16 0x56415c700586 <unknown>\n#17 0x7f8a8609caa4 <unknown>\n#18 0x7f8a86129c3c <unknown>\n\n","statusTrace":"  File \"/opt/hostedtoolcache/Python/3.10.18/x64/lib/python3.10/site-packages/behave/model.py\", line 1329, in run\n    match.run(runner.context)\n  File \"/opt/hostedtoolcache/Python/3.10.18/x64/lib/python3.10/site-packages/behave/matchers.py\", line 98, in run\n    self.func(context, *args, **kwargs)\n  File \"features/steps/login_steps.py\", line 12, in step_user_on_login_page\n    context.driver = webdriver.Chrome()\n  File \"/opt/hostedtoolcache/Python/3.10.18/x64/lib/python3.10/site-packages/selenium/webdriver/chrome/webdriver.py\", line 47, in __init__\n    super().__init__(\n  File \"/opt/hostedtoolcache/Python/3.10.18/x64/lib/python3.10/site-packages/selenium/webdriver/chromium/webdriver.py\", line 69, in __init__\n    super().__init__(command_executor=executor, options=options)\n  File \"/opt/hostedtoolcache/Python/3.10.18/x64/lib/python3.10/site-packages/selenium/webdriver/remote/webdriver.py\", line 261, in __init__\n    self.start_session(capabilities)\n  File \"/opt/hostedtoolcache/Python/3.10.18/x64/lib/python3.10/site-packages/selenium/webdriver/remote/webdriver.py\", line 362, in start_session\n    response = self.execute(Command.NEW_SESSION, caps)[\"value\"]\n  File \"/opt/hostedtoolcache/Python/3.10.18/x64/lib/python3.10/site-packages/selenium/webdriver/remote/webdriver.py\", line 454, in execute\n    self.error_handler.check_response(response)\n  File \"/opt/hostedtoolcache/Python/3.10.18/x64/lib/python3.10/site-packages/selenium/webdriver/remote/errorhandler.py\", line 232, in check_response\n    raise exception_class(message, screen, stacktrace)\n","steps":[],"attachments":[],"parameters":[],"shouldDisplayMessage":true,"stepsCount":0,"attachmentsCount":0,"hasContent":true,"attachmentStep":false},{"name":"When the user enters username \"standard_user\" and password \"wrong_pass\"","time":{"start":1752092569608,"stop":1752092569608,"duration":0},"status":"skipped","steps":[],"attachments":[],"parameters":[],"shouldDisplayMessage":false,"stepsCount":0,"attachmentsCount":0,"hasContent":false,"attachmentStep":false},{"name":"Then the user should see an error message","time":{"start":1752092569608,"stop":1752092569608,"duration":0},"status":"skipped","steps":[],"attachments":[],"parameters":[],"shouldDisplayMessage":false,"stepsCount":0,"attachmentsCount":0,"hasContent":false,"attachmentStep":false}],"attachments":[],"parameters":[],"shouldDisplayMessage":false,"stepsCount":3,"attachmentsCount":0,"hasContent":true,"attachmentStep":false},"afterStages":[],"labels":[{"name":"severity","value":"normal"},{"name":"tag","value":"smoke"},{"name":"feature","value":"Login functionality on saucedemo"},{"name":"framework","value":"behave"},{"name":"language","value":"cpython3"},{"name":"resultFormat","value":"allure2"}],"parameters":[{"name":"password","value":"wrong_pass"},{"name":"username","value":"standard_user"}],"links":[],"hidden":false,"retry":false,"extra":{"severity":"normal","retries":[],"categories":[{"name":"Test defects","matchedStatuses":[],"flaky":false}],"tags":["smoke"]},"source":"decfbc4cdf88c971.json","parameterValues":["wrong_pass","standard_user"]}