{"uid":"e46bd1e3c0a00bd0","name":"User logs in with invalid credentials -- @1.4 ","fullName":"Login functionality on saucedemo: User logs in with invalid credentials","historyId":"8f3b39a058c9cc4fd3e998f449b073a9","time":{"start":1752092570076,"stop":1752092570274,"duration":198},"status":"broken","statusMessage":"selenium.common.exceptions.SessionNotCreatedException: Message: session not created: probably user data directory is already in use, please specify a unique value for --user-data-dir argument, or don't use --user-data-dir; For documentation on this error, please visit: https://www.selenium.dev/documentation/webdriver/troubleshooting/errors#sessionnotcreatedexception\nStacktrace:\n#0 0x555e915db26a <unknown>\n#1 0x555e91085ab0 <unknown>\n#2 0x555e910c08ac <unknown>\n#3 0x555e910bb307 <unknown>\n#4 0x555e9110b696 <unknown>\n#5 0x555e9110ad56 <unknown>\n#6 0x555e910fcf73 <unknown>\n#7 0x555e910c9aeb <unknown>\n#8 0x555e910ca751 <unknown>\n#9 0x555e9159fb7b <unknown>\n#10 0x555e915a3959 <unknown>\n#11 0x555e91586959 <unknown>\n#12 0x555e915a4518 <unknown>\n#13 0x555e9156b10f <unknown>\n#14 0x555e915c8918 <unknown>\n#15 0x555e915c8af6 <unknown>\n#16 0x555e915da586 <unknown>\n#17 0x7fbf3e49caa4 <unknown>\n#18 0x7fbf3e529c3c <unknown>\n\n","statusTrace":"  File \"/opt/hostedtoolcache/Python/3.10.18/x64/lib/python3.10/site-packages/behave/model.py\", line 1329, in run\n    match.run(runner.context)\n  File \"/opt/hostedtoolcache/Python/3.10.18/x64/lib/python3.10/site-packages/behave/matchers.py\", line 98, in run\n    self.func(context, *args, **kwargs)\n  File \"features/steps/login_steps.py\", line 12, in step_user_on_login_page\n    context.driver = webdriver.Chrome()\n  File \"/opt/hostedtoolcache/Python/3.10.18/x64/lib/python3.10/site-packages/selenium/webdriver/chrome/webdriver.py\", line 47, in __init__\n    super().__init__(\n  File \"/opt/hostedtoolcache/Python/3.10.18/x64/lib/python3.10/site-packages/selenium/webdriver/chromium/webdriver.py\", line 69, in __init__\n    super().__init__(command_executor=executor, options=options)\n  File \"/opt/hostedtoolcache/Python/3.10.18/x64/lib/python3.10/site-packages/selenium/webdriver/remote/webdriver.py\", line 261, in __init__\n    self.start_session(capabilities)\n  File \"/opt/hostedtoolcache/Python/3.10.18/x64/lib/python3.10/site-packages/selenium/webdriver/remote/webdriver.py\", line 362, in start_session\n    response = self.execute(Command.NEW_SESSION, caps)[\"value\"]\n  File \"/opt/hostedtoolcache/Python/3.10.18/x64/lib/python3.10/site-packages/selenium/webdriver/remote/webdriver.py\", line 454, in execute\n    self.error_handler.check_response(response)\n  File \"/opt/hostedtoolcache/Python/3.10.18/x64/lib/python3.10/site-packages/selenium/webdriver/remote/errorhandler.py\", line 232, in check_response\n    raise exception_class(message, screen, stacktrace)\n","flaky":false,"newFailed":false,"newBroken":false,"newPassed":false,"retriesCount":0,"retriesStatusChange":false,"beforeStages":[],"testStage":{"status":"broken","statusMessage":"selenium.common.exceptions.SessionNotCreatedException: Message: session not created: probably user data directory is already in use, please specify a unique value for --user-data-dir argument, or don't use --user-data-dir; For documentation on this error, please visit: https://www.selenium.dev/documentation/webdriver/troubleshooting/errors#sessionnotcreatedexception\nStacktrace:\n#0 0x555e915db26a <unknown>\n#1 0x555e91085ab0 <unknown>\n#2 0x555e910c08ac <unknown>\n#3 0x555e910bb307 <unknown>\n#4 0x555e9110b696 <unknown>\n#5 0x555e9110ad56 <unknown>\n#6 0x555e910fcf73 <unknown>\n#7 0x555e910c9aeb <unknown>\n#8 0x555e910ca751 <unknown>\n#9 0x555e9159fb7b <unknown>\n#10 0x555e915a3959 <unknown>\n#11 0x555e91586959 <unknown>\n#12 0x555e915a4518 <unknown>\n#13 0x555e9156b10f <unknown>\n#14 0x555e915c8918 <unknown>\n#15 0x555e915c8af6 <unknown>\n#16 0x555e915da586 <unknown>\n#17 0x7fbf3e49caa4 <unknown>\n#18 0x7fbf3e529c3c <unknown>\n\n","statusTrace":"  File \"/opt/hostedtoolcache/Python/3.10.18/x64/lib/python3.10/site-packages/behave/model.py\", line 1329, in run\n    match.run(runner.context)\n  File \"/opt/hostedtoolcache/Python/3.10.18/x64/lib/python3.10/site-packages/behave/matchers.py\", line 98, in run\n    self.func(context, *args, **kwargs)\n  File \"features/steps/login_steps.py\", line 12, in step_user_on_login_page\n    context.driver = webdriver.Chrome()\n  File \"/opt/hostedtoolcache/Python/3.10.18/x64/lib/python3.10/site-packages/selenium/webdriver/chrome/webdriver.py\", line 47, in __init__\n    super().__init__(\n  File \"/opt/hostedtoolcache/Python/3.10.18/x64/lib/python3.10/site-packages/selenium/webdriver/chromium/webdriver.py\", line 69, in __init__\n    super().__init__(command_executor=executor, options=options)\n  File \"/opt/hostedtoolcache/Python/3.10.18/x64/lib/python3.10/site-packages/selenium/webdriver/remote/webdriver.py\", line 261, in __init__\n    self.start_session(capabilities)\n  File \"/opt/hostedtoolcache/Python/3.10.18/x64/lib/python3.10/site-packages/selenium/webdriver/remote/webdriver.py\", line 362, in start_session\n    response = self.execute(Command.NEW_SESSION, caps)[\"value\"]\n  File \"/opt/hostedtoolcache/Python/3.10.18/x64/lib/python3.10/site-packages/selenium/webdriver/remote/webdriver.py\", line 454, in execute\n    self.error_handler.check_response(response)\n  File \"/opt/hostedtoolcache/Python/3.10.18/x64/lib/python3.10/site-packages/selenium/webdriver/remote/errorhandler.py\", line 232, in check_response\n    raise exception_class(message, screen, stacktrace)\n","steps":[{"name":"Given the user is on the saucedemo login page","time":{"start":1752092570076,"stop":1752092570274,"duration":198},"status":"broken","statusMessage":"selenium.common.exceptions.SessionNotCreatedException: Message: session not created: probably user data directory is already in use, please specify a unique value for --user-data-dir argument, or don't use --user-data-dir; For documentation on this error, please visit: https://www.selenium.dev/documentation/webdriver/troubleshooting/errors#sessionnotcreatedexception\nStacktrace:\n#0 0x555e915db26a <unknown>\n#1 0x555e91085ab0 <unknown>\n#2 0x555e910c08ac <unknown>\n#3 0x555e910bb307 <unknown>\n#4 0x555e9110b696 <unknown>\n#5 0x555e9110ad56 <unknown>\n#6 0x555e910fcf73 <unknown>\n#7 0x555e910c9aeb <unknown>\n#8 0x555e910ca751 <unknown>\n#9 0x555e9159fb7b <unknown>\n#10 0x555e915a3959 <unknown>\n#11 0x555e91586959 <unknown>\n#12 0x555e915a4518 <unknown>\n#13 0x555e9156b10f <unknown>\n#14 0x555e915c8918 <unknown>\n#15 0x555e915c8af6 <unknown>\n#16 0x555e915da586 <unknown>\n#17 0x7fbf3e49caa4 <unknown>\n#18 0x7fbf3e529c3c <unknown>\n\n","statusTrace":"  File \"/opt/hostedtoolcache/Python/3.10.18/x64/lib/python3.10/site-packages/behave/model.py\", line 1329, in run\n    match.run(runner.context)\n  File \"/opt/hostedtoolcache/Python/3.10.18/x64/lib/python3.10/site-packages/behave/matchers.py\", line 98, in run\n    self.func(context, *args, **kwargs)\n  File \"features/steps/login_steps.py\", line 12, in step_user_on_login_page\n    context.driver = webdriver.Chrome()\n  File \"/opt/hostedtoolcache/Python/3.10.18/x64/lib/python3.10/site-packages/selenium/webdriver/chrome/webdriver.py\", line 47, in __init__\n    super().__init__(\n  File \"/opt/hostedtoolcache/Python/3.10.18/x64/lib/python3.10/site-packages/selenium/webdriver/chromium/webdriver.py\", line 69, in __init__\n    super().__init__(command_executor=executor, options=options)\n  File \"/opt/hostedtoolcache/Python/3.10.18/x64/lib/python3.10/site-packages/selenium/webdriver/remote/webdriver.py\", line 261, in __init__\n    self.start_session(capabilities)\n  File \"/opt/hostedtoolcache/Python/3.10.18/x64/lib/python3.10/site-packages/selenium/webdriver/remote/webdriver.py\", line 362, in start_session\n    response = self.execute(Command.NEW_SESSION, caps)[\"value\"]\n  File \"/opt/hostedtoolcache/Python/3.10.18/x64/lib/python3.10/site-packages/selenium/webdriver/remote/webdriver.py\", line 454, in execute\n    self.error_handler.check_response(response)\n  File \"/opt/hostedtoolcache/Python/3.10.18/x64/lib/python3.10/site-packages/selenium/webdriver/remote/errorhandler.py\", line 232, in check_response\n    raise exception_class(message, screen, stacktrace)\n","steps":[],"attachments":[],"parameters":[],"shouldDisplayMessage":true,"stepsCount":0,"attachmentsCount":0,"hasContent":true,"attachmentStep":false},{"name":"When the user enters username \"standard_user\" and password \"\"","time":{"start":1752092570274,"stop":1752092570274,"duration":0},"status":"broken","statusMessage":"\nYou can implement step definitions for undefined steps with these snippets:\n\n@when(u'the user enters username \"standard_user\" and password \"\"')\ndef step_impl(context):\n    raise NotImplementedError(u'STEP: When the user enters username \"standard_user\" and password \"\"')\n\n","steps":[],"attachments":[],"parameters":[],"shouldDisplayMessage":true,"stepsCount":0,"attachmentsCount":0,"hasContent":true,"attachmentStep":false},{"name":"Then the user should see an error message","time":{"start":1752092570274,"stop":1752092570274,"duration":0},"status":"skipped","steps":[],"attachments":[],"parameters":[],"shouldDisplayMessage":false,"stepsCount":0,"attachmentsCount":0,"hasContent":false,"attachmentStep":false}],"attachments":[],"parameters":[],"shouldDisplayMessage":false,"stepsCount":3,"attachmentsCount":0,"hasContent":true,"attachmentStep":false},"afterStages":[],"labels":[{"name":"severity","value":"normal"},{"name":"tag","value":"smoke"},{"name":"feature","value":"Login functionality on saucedemo"},{"name":"framework","value":"behave"},{"name":"language","value":"cpython3"},{"name":"resultFormat","value":"allure2"}],"parameters":[{"name":"password"},{"name":"username","value":"standard_user"}],"links":[],"hidden":false,"retry":false,"extra":{"severity":"normal","retries":[],"categories":[{"name":"Test defects","matchedStatuses":[],"flaky":false}],"tags":["smoke"]},"source":"e46bd1e3c0a00bd0.json","parameterValues":[null,"standard_user"]}