{"uid":"e48e73e1b587ca30","name":"User logs in with invalid credentials -- @1.2 ","fullName":"Login functionality on saucedemo: User logs in with invalid credentials","historyId":"a22229db0b99d8e750235352d677fdc2","time":{"start":1752092569609,"stop":1752092569874,"duration":265},"status":"broken","statusMessage":"selenium.common.exceptions.SessionNotCreatedException: Message: session not created: probably user data directory is already in use, please specify a unique value for --user-data-dir argument, or don't use --user-data-dir; For documentation on this error, please visit: https://www.selenium.dev/documentation/webdriver/troubleshooting/errors#sessionnotcreatedexception\nStacktrace:\n#0 0x55b2881c226a <unknown>\n#1 0x55b287c6cab0 <unknown>\n#2 0x55b287ca78ac <unknown>\n#3 0x55b287ca2307 <unknown>\n#4 0x55b287cf2696 <unknown>\n#5 0x55b287cf1d56 <unknown>\n#6 0x55b287ce3f73 <unknown>\n#7 0x55b287cb0aeb <unknown>\n#8 0x55b287cb1751 <unknown>\n#9 0x55b288186b7b <unknown>\n#10 0x55b28818a959 <unknown>\n#11 0x55b28816d959 <unknown>\n#12 0x55b28818b518 <unknown>\n#13 0x55b28815210f <unknown>\n#14 0x55b2881af918 <unknown>\n#15 0x55b2881afaf6 <unknown>\n#16 0x55b2881c1586 <unknown>\n#17 0x7f56d8e9caa4 <unknown>\n#18 0x7f56d8f29c3c <unknown>\n\n","statusTrace":"  File \"/opt/hostedtoolcache/Python/3.10.18/x64/lib/python3.10/site-packages/behave/model.py\", line 1329, in run\n    match.run(runner.context)\n  File \"/opt/hostedtoolcache/Python/3.10.18/x64/lib/python3.10/site-packages/behave/matchers.py\", line 98, in run\n    self.func(context, *args, **kwargs)\n  File \"features/steps/login_steps.py\", line 12, in step_user_on_login_page\n    context.driver = webdriver.Chrome()\n  File \"/opt/hostedtoolcache/Python/3.10.18/x64/lib/python3.10/site-packages/selenium/webdriver/chrome/webdriver.py\", line 47, in __init__\n    super().__init__(\n  File \"/opt/hostedtoolcache/Python/3.10.18/x64/lib/python3.10/site-packages/selenium/webdriver/chromium/webdriver.py\", line 69, in __init__\n    super().__init__(command_executor=executor, options=options)\n  File \"/opt/hostedtoolcache/Python/3.10.18/x64/lib/python3.10/site-packages/selenium/webdriver/remote/webdriver.py\", line 261, in __init__\n    self.start_session(capabilities)\n  File \"/opt/hostedtoolcache/Python/3.10.18/x64/lib/python3.10/site-packages/selenium/webdriver/remote/webdriver.py\", line 362, in start_session\n    response = self.execute(Command.NEW_SESSION, caps)[\"value\"]\n  File \"/opt/hostedtoolcache/Python/3.10.18/x64/lib/python3.10/site-packages/selenium/webdriver/remote/webdriver.py\", line 454, in execute\n    self.error_handler.check_response(response)\n  File \"/opt/hostedtoolcache/Python/3.10.18/x64/lib/python3.10/site-packages/selenium/webdriver/remote/errorhandler.py\", line 232, in check_response\n    raise exception_class(message, screen, stacktrace)\n","flaky":false,"newFailed":false,"newBroken":false,"newPassed":false,"retriesCount":0,"retriesStatusChange":false,"beforeStages":[],"testStage":{"status":"broken","statusMessage":"selenium.common.exceptions.SessionNotCreatedException: Message: session not created: probably user data directory is already in use, please specify a unique value for --user-data-dir argument, or don't use --user-data-dir; For documentation on this error, please visit: https://www.selenium.dev/documentation/webdriver/troubleshooting/errors#sessionnotcreatedexception\nStacktrace:\n#0 0x55b2881c226a <unknown>\n#1 0x55b287c6cab0 <unknown>\n#2 0x55b287ca78ac <unknown>\n#3 0x55b287ca2307 <unknown>\n#4 0x55b287cf2696 <unknown>\n#5 0x55b287cf1d56 <unknown>\n#6 0x55b287ce3f73 <unknown>\n#7 0x55b287cb0aeb <unknown>\n#8 0x55b287cb1751 <unknown>\n#9 0x55b288186b7b <unknown>\n#10 0x55b28818a959 <unknown>\n#11 0x55b28816d959 <unknown>\n#12 0x55b28818b518 <unknown>\n#13 0x55b28815210f <unknown>\n#14 0x55b2881af918 <unknown>\n#15 0x55b2881afaf6 <unknown>\n#16 0x55b2881c1586 <unknown>\n#17 0x7f56d8e9caa4 <unknown>\n#18 0x7f56d8f29c3c <unknown>\n\n","statusTrace":"  File \"/opt/hostedtoolcache/Python/3.10.18/x64/lib/python3.10/site-packages/behave/model.py\", line 1329, in run\n    match.run(runner.context)\n  File \"/opt/hostedtoolcache/Python/3.10.18/x64/lib/python3.10/site-packages/behave/matchers.py\", line 98, in run\n    self.func(context, *args, **kwargs)\n  File \"features/steps/login_steps.py\", line 12, in step_user_on_login_page\n    context.driver = webdriver.Chrome()\n  File \"/opt/hostedtoolcache/Python/3.10.18/x64/lib/python3.10/site-packages/selenium/webdriver/chrome/webdriver.py\", line 47, in __init__\n    super().__init__(\n  File \"/opt/hostedtoolcache/Python/3.10.18/x64/lib/python3.10/site-packages/selenium/webdriver/chromium/webdriver.py\", line 69, in __init__\n    super().__init__(command_executor=executor, options=options)\n  File \"/opt/hostedtoolcache/Python/3.10.18/x64/lib/python3.10/site-packages/selenium/webdriver/remote/webdriver.py\", line 261, in __init__\n    self.start_session(capabilities)\n  File \"/opt/hostedtoolcache/Python/3.10.18/x64/lib/python3.10/site-packages/selenium/webdriver/remote/webdriver.py\", line 362, in start_session\n    response = self.execute(Command.NEW_SESSION, caps)[\"value\"]\n  File \"/opt/hostedtoolcache/Python/3.10.18/x64/lib/python3.10/site-packages/selenium/webdriver/remote/webdriver.py\", line 454, in execute\n    self.error_handler.check_response(response)\n  File \"/opt/hostedtoolcache/Python/3.10.18/x64/lib/python3.10/site-packages/selenium/webdriver/remote/errorhandler.py\", line 232, in check_response\n    raise exception_class(message, screen, stacktrace)\n","steps":[{"name":"Given the user is on the saucedemo login page","time":{"start":1752092569609,"stop":1752092569874,"duration":265},"status":"broken","statusMessage":"selenium.common.exceptions.SessionNotCreatedException: Message: session not created: probably user data directory is already in use, please specify a unique value for --user-data-dir argument, or don't use --user-data-dir; For documentation on this error, please visit: https://www.selenium.dev/documentation/webdriver/troubleshooting/errors#sessionnotcreatedexception\nStacktrace:\n#0 0x55b2881c226a <unknown>\n#1 0x55b287c6cab0 <unknown>\n#2 0x55b287ca78ac <unknown>\n#3 0x55b287ca2307 <unknown>\n#4 0x55b287cf2696 <unknown>\n#5 0x55b287cf1d56 <unknown>\n#6 0x55b287ce3f73 <unknown>\n#7 0x55b287cb0aeb <unknown>\n#8 0x55b287cb1751 <unknown>\n#9 0x55b288186b7b <unknown>\n#10 0x55b28818a959 <unknown>\n#11 0x55b28816d959 <unknown>\n#12 0x55b28818b518 <unknown>\n#13 0x55b28815210f <unknown>\n#14 0x55b2881af918 <unknown>\n#15 0x55b2881afaf6 <unknown>\n#16 0x55b2881c1586 <unknown>\n#17 0x7f56d8e9caa4 <unknown>\n#18 0x7f56d8f29c3c <unknown>\n\n","statusTrace":"  File \"/opt/hostedtoolcache/Python/3.10.18/x64/lib/python3.10/site-packages/behave/model.py\", line 1329, in run\n    match.run(runner.context)\n  File \"/opt/hostedtoolcache/Python/3.10.18/x64/lib/python3.10/site-packages/behave/matchers.py\", line 98, in run\n    self.func(context, *args, **kwargs)\n  File \"features/steps/login_steps.py\", line 12, in step_user_on_login_page\n    context.driver = webdriver.Chrome()\n  File \"/opt/hostedtoolcache/Python/3.10.18/x64/lib/python3.10/site-packages/selenium/webdriver/chrome/webdriver.py\", line 47, in __init__\n    super().__init__(\n  File \"/opt/hostedtoolcache/Python/3.10.18/x64/lib/python3.10/site-packages/selenium/webdriver/chromium/webdriver.py\", line 69, in __init__\n    super().__init__(command_executor=executor, options=options)\n  File \"/opt/hostedtoolcache/Python/3.10.18/x64/lib/python3.10/site-packages/selenium/webdriver/remote/webdriver.py\", line 261, in __init__\n    self.start_session(capabilities)\n  File \"/opt/hostedtoolcache/Python/3.10.18/x64/lib/python3.10/site-packages/selenium/webdriver/remote/webdriver.py\", line 362, in start_session\n    response = self.execute(Command.NEW_SESSION, caps)[\"value\"]\n  File \"/opt/hostedtoolcache/Python/3.10.18/x64/lib/python3.10/site-packages/selenium/webdriver/remote/webdriver.py\", line 454, in execute\n    self.error_handler.check_response(response)\n  File \"/opt/hostedtoolcache/Python/3.10.18/x64/lib/python3.10/site-packages/selenium/webdriver/remote/errorhandler.py\", line 232, in check_response\n    raise exception_class(message, screen, stacktrace)\n","steps":[],"attachments":[],"parameters":[],"shouldDisplayMessage":true,"stepsCount":0,"attachmentsCount":0,"hasContent":true,"attachmentStep":false},{"name":"When the user enters username \"locked_out_user\" and password \"secret_sauce\"","time":{"start":1752092569874,"stop":1752092569874,"duration":0},"status":"skipped","steps":[],"attachments":[],"parameters":[],"shouldDisplayMessage":false,"stepsCount":0,"attachmentsCount":0,"hasContent":false,"attachmentStep":false},{"name":"Then the user should see an error message","time":{"start":1752092569874,"stop":1752092569874,"duration":0},"status":"skipped","steps":[],"attachments":[],"parameters":[],"shouldDisplayMessage":false,"stepsCount":0,"attachmentsCount":0,"hasContent":false,"attachmentStep":false}],"attachments":[],"parameters":[],"shouldDisplayMessage":false,"stepsCount":3,"attachmentsCount":0,"hasContent":true,"attachmentStep":false},"afterStages":[],"labels":[{"name":"severity","value":"normal"},{"name":"tag","value":"smoke"},{"name":"feature","value":"Login functionality on saucedemo"},{"name":"framework","value":"behave"},{"name":"language","value":"cpython3"},{"name":"resultFormat","value":"allure2"}],"parameters":[{"name":"password","value":"secret_sauce"},{"name":"username","value":"locked_out_user"}],"links":[],"hidden":false,"retry":false,"extra":{"severity":"normal","retries":[],"categories":[{"name":"Test defects","matchedStatuses":[],"flaky":false}],"tags":["smoke"]},"source":"e48e73e1b587ca30.json","parameterValues":["secret_sauce","locked_out_user"]}