{"uid":"e8c744d3f9790391","name":"User logs in with invalid credentials -- @1.5 ","fullName":"Login functionality on saucedemo: User logs in with invalid credentials","historyId":"79e31430455f7f67708e35ce856911bc","time":{"start":1752092570275,"stop":1752092570485,"duration":210},"status":"broken","statusMessage":"selenium.common.exceptions.SessionNotCreatedException: Message: session not created: probably user data directory is already in use, please specify a unique value for --user-data-dir argument, or don't use --user-data-dir; For documentation on this error, please visit: https://www.selenium.dev/documentation/webdriver/troubleshooting/errors#sessionnotcreatedexception\nStacktrace:\n#0 0x5560b5f0326a <unknown>\n#1 0x5560b59adab0 <unknown>\n#2 0x5560b59e88ac <unknown>\n#3 0x5560b59e3307 <unknown>\n#4 0x5560b5a33696 <unknown>\n#5 0x5560b5a32d56 <unknown>\n#6 0x5560b5a24f73 <unknown>\n#7 0x5560b59f1aeb <unknown>\n#8 0x5560b59f2751 <unknown>\n#9 0x5560b5ec7b7b <unknown>\n#10 0x5560b5ecb959 <unknown>\n#11 0x5560b5eae959 <unknown>\n#12 0x5560b5ecc518 <unknown>\n#13 0x5560b5e9310f <unknown>\n#14 0x5560b5ef0918 <unknown>\n#15 0x5560b5ef0af6 <unknown>\n#16 0x5560b5f02586 <unknown>\n#17 0x7f538669caa4 <unknown>\n#18 0x7f5386729c3c <unknown>\n\n","statusTrace":"  File \"/opt/hostedtoolcache/Python/3.10.18/x64/lib/python3.10/site-packages/behave/model.py\", line 1329, in run\n    match.run(runner.context)\n  File \"/opt/hostedtoolcache/Python/3.10.18/x64/lib/python3.10/site-packages/behave/matchers.py\", line 98, in run\n    self.func(context, *args, **kwargs)\n  File \"features/steps/login_steps.py\", line 12, in step_user_on_login_page\n    context.driver = webdriver.Chrome()\n  File \"/opt/hostedtoolcache/Python/3.10.18/x64/lib/python3.10/site-packages/selenium/webdriver/chrome/webdriver.py\", line 47, in __init__\n    super().__init__(\n  File \"/opt/hostedtoolcache/Python/3.10.18/x64/lib/python3.10/site-packages/selenium/webdriver/chromium/webdriver.py\", line 69, in __init__\n    super().__init__(command_executor=executor, options=options)\n  File \"/opt/hostedtoolcache/Python/3.10.18/x64/lib/python3.10/site-packages/selenium/webdriver/remote/webdriver.py\", line 261, in __init__\n    self.start_session(capabilities)\n  File \"/opt/hostedtoolcache/Python/3.10.18/x64/lib/python3.10/site-packages/selenium/webdriver/remote/webdriver.py\", line 362, in start_session\n    response = self.execute(Command.NEW_SESSION, caps)[\"value\"]\n  File \"/opt/hostedtoolcache/Python/3.10.18/x64/lib/python3.10/site-packages/selenium/webdriver/remote/webdriver.py\", line 454, in execute\n    self.error_handler.check_response(response)\n  File \"/opt/hostedtoolcache/Python/3.10.18/x64/lib/python3.10/site-packages/selenium/webdriver/remote/errorhandler.py\", line 232, in check_response\n    raise exception_class(message, screen, stacktrace)\n","flaky":false,"newFailed":false,"newBroken":false,"newPassed":false,"retriesCount":0,"retriesStatusChange":false,"beforeStages":[],"testStage":{"status":"broken","statusMessage":"selenium.common.exceptions.SessionNotCreatedException: Message: session not created: probably user data directory is already in use, please specify a unique value for --user-data-dir argument, or don't use --user-data-dir; For documentation on this error, please visit: https://www.selenium.dev/documentation/webdriver/troubleshooting/errors#sessionnotcreatedexception\nStacktrace:\n#0 0x5560b5f0326a <unknown>\n#1 0x5560b59adab0 <unknown>\n#2 0x5560b59e88ac <unknown>\n#3 0x5560b59e3307 <unknown>\n#4 0x5560b5a33696 <unknown>\n#5 0x5560b5a32d56 <unknown>\n#6 0x5560b5a24f73 <unknown>\n#7 0x5560b59f1aeb <unknown>\n#8 0x5560b59f2751 <unknown>\n#9 0x5560b5ec7b7b <unknown>\n#10 0x5560b5ecb959 <unknown>\n#11 0x5560b5eae959 <unknown>\n#12 0x5560b5ecc518 <unknown>\n#13 0x5560b5e9310f <unknown>\n#14 0x5560b5ef0918 <unknown>\n#15 0x5560b5ef0af6 <unknown>\n#16 0x5560b5f02586 <unknown>\n#17 0x7f538669caa4 <unknown>\n#18 0x7f5386729c3c <unknown>\n\n","statusTrace":"  File \"/opt/hostedtoolcache/Python/3.10.18/x64/lib/python3.10/site-packages/behave/model.py\", line 1329, in run\n    match.run(runner.context)\n  File \"/opt/hostedtoolcache/Python/3.10.18/x64/lib/python3.10/site-packages/behave/matchers.py\", line 98, in run\n    self.func(context, *args, **kwargs)\n  File \"features/steps/login_steps.py\", line 12, in step_user_on_login_page\n    context.driver = webdriver.Chrome()\n  File \"/opt/hostedtoolcache/Python/3.10.18/x64/lib/python3.10/site-packages/selenium/webdriver/chrome/webdriver.py\", line 47, in __init__\n    super().__init__(\n  File \"/opt/hostedtoolcache/Python/3.10.18/x64/lib/python3.10/site-packages/selenium/webdriver/chromium/webdriver.py\", line 69, in __init__\n    super().__init__(command_executor=executor, options=options)\n  File \"/opt/hostedtoolcache/Python/3.10.18/x64/lib/python3.10/site-packages/selenium/webdriver/remote/webdriver.py\", line 261, in __init__\n    self.start_session(capabilities)\n  File \"/opt/hostedtoolcache/Python/3.10.18/x64/lib/python3.10/site-packages/selenium/webdriver/remote/webdriver.py\", line 362, in start_session\n    response = self.execute(Command.NEW_SESSION, caps)[\"value\"]\n  File \"/opt/hostedtoolcache/Python/3.10.18/x64/lib/python3.10/site-packages/selenium/webdriver/remote/webdriver.py\", line 454, in execute\n    self.error_handler.check_response(response)\n  File \"/opt/hostedtoolcache/Python/3.10.18/x64/lib/python3.10/site-packages/selenium/webdriver/remote/errorhandler.py\", line 232, in check_response\n    raise exception_class(message, screen, stacktrace)\n","steps":[{"name":"Given the user is on the saucedemo login page","time":{"start":1752092570276,"stop":1752092570485,"duration":209},"status":"broken","statusMessage":"selenium.common.exceptions.SessionNotCreatedException: Message: session not created: probably user data directory is already in use, please specify a unique value for --user-data-dir argument, or don't use --user-data-dir; For documentation on this error, please visit: https://www.selenium.dev/documentation/webdriver/troubleshooting/errors#sessionnotcreatedexception\nStacktrace:\n#0 0x5560b5f0326a <unknown>\n#1 0x5560b59adab0 <unknown>\n#2 0x5560b59e88ac <unknown>\n#3 0x5560b59e3307 <unknown>\n#4 0x5560b5a33696 <unknown>\n#5 0x5560b5a32d56 <unknown>\n#6 0x5560b5a24f73 <unknown>\n#7 0x5560b59f1aeb <unknown>\n#8 0x5560b59f2751 <unknown>\n#9 0x5560b5ec7b7b <unknown>\n#10 0x5560b5ecb959 <unknown>\n#11 0x5560b5eae959 <unknown>\n#12 0x5560b5ecc518 <unknown>\n#13 0x5560b5e9310f <unknown>\n#14 0x5560b5ef0918 <unknown>\n#15 0x5560b5ef0af6 <unknown>\n#16 0x5560b5f02586 <unknown>\n#17 0x7f538669caa4 <unknown>\n#18 0x7f5386729c3c <unknown>\n\n","statusTrace":"  File \"/opt/hostedtoolcache/Python/3.10.18/x64/lib/python3.10/site-packages/behave/model.py\", line 1329, in run\n    match.run(runner.context)\n  File \"/opt/hostedtoolcache/Python/3.10.18/x64/lib/python3.10/site-packages/behave/matchers.py\", line 98, in run\n    self.func(context, *args, **kwargs)\n  File \"features/steps/login_steps.py\", line 12, in step_user_on_login_page\n    context.driver = webdriver.Chrome()\n  File \"/opt/hostedtoolcache/Python/3.10.18/x64/lib/python3.10/site-packages/selenium/webdriver/chrome/webdriver.py\", line 47, in __init__\n    super().__init__(\n  File \"/opt/hostedtoolcache/Python/3.10.18/x64/lib/python3.10/site-packages/selenium/webdriver/chromium/webdriver.py\", line 69, in __init__\n    super().__init__(command_executor=executor, options=options)\n  File \"/opt/hostedtoolcache/Python/3.10.18/x64/lib/python3.10/site-packages/selenium/webdriver/remote/webdriver.py\", line 261, in __init__\n    self.start_session(capabilities)\n  File \"/opt/hostedtoolcache/Python/3.10.18/x64/lib/python3.10/site-packages/selenium/webdriver/remote/webdriver.py\", line 362, in start_session\n    response = self.execute(Command.NEW_SESSION, caps)[\"value\"]\n  File \"/opt/hostedtoolcache/Python/3.10.18/x64/lib/python3.10/site-packages/selenium/webdriver/remote/webdriver.py\", line 454, in execute\n    self.error_handler.check_response(response)\n  File \"/opt/hostedtoolcache/Python/3.10.18/x64/lib/python3.10/site-packages/selenium/webdriver/remote/errorhandler.py\", line 232, in check_response\n    raise exception_class(message, screen, stacktrace)\n","steps":[],"attachments":[],"parameters":[],"shouldDisplayMessage":true,"stepsCount":0,"attachmentsCount":0,"hasContent":true,"attachmentStep":false},{"name":"When the user enters username \"\" and password \"\"","time":{"start":1752092570485,"stop":1752092570485,"duration":0},"status":"broken","statusMessage":"\nYou can implement step definitions for undefined steps with these snippets:\n\n@when(u'the user enters username \"\" and password \"\"')\ndef step_impl(context):\n    raise NotImplementedError(u'STEP: When the user enters username \"\" and password \"\"')\n\n","steps":[],"attachments":[],"parameters":[],"shouldDisplayMessage":true,"stepsCount":0,"attachmentsCount":0,"hasContent":true,"attachmentStep":false},{"name":"Then the user should see an error message","time":{"start":1752092570485,"stop":1752092570485,"duration":0},"status":"skipped","steps":[],"attachments":[],"parameters":[],"shouldDisplayMessage":false,"stepsCount":0,"attachmentsCount":0,"hasContent":false,"attachmentStep":false}],"attachments":[],"parameters":[],"shouldDisplayMessage":false,"stepsCount":3,"attachmentsCount":0,"hasContent":true,"attachmentStep":false},"afterStages":[],"labels":[{"name":"severity","value":"normal"},{"name":"tag","value":"smoke"},{"name":"feature","value":"Login functionality on saucedemo"},{"name":"framework","value":"behave"},{"name":"language","value":"cpython3"},{"name":"resultFormat","value":"allure2"}],"parameters":[{"name":"password"},{"name":"username"}],"links":[],"hidden":false,"retry":false,"extra":{"severity":"normal","retries":[],"categories":[{"name":"Test defects","matchedStatuses":[],"flaky":false}],"tags":["smoke"]},"source":"e8c744d3f9790391.json","parameterValues":[null,null]}